<?xml version="1.0"?>
<robot name="example_robot">

    <!-- Definir materiales -->
    <material name="red">
        <color rgba="1 0 0 1"/>
    </material>
    <material name="blue">
        <color rgba="0 0 1 1"/>
    </material>

    <link name="link0_passive">
        <visual>
            <origin xyz="0 0 0" rpy="0 0 0"/>
            <material name="blue"/>
            <geometry>
                <cylinder length="0.1" radius="0.05"/>
            </geometry>
        </visual>
    </link>

    <link name="link0_x_axis">
        <visual>
            <origin xyz="0 0 0" rpy="0 0 0"/>
            <material name="red"/>
            <geometry>
                <cylinder length="0.1" radius="0.05"/>
            </geometry>
        </visual>
    </link>

    <joint name="q0_x" type="fixed">
        <origin xyz="0 0 0" rpy="0 1.571 0"/>
        <parent link="link0_passive"/>
        <child link="link0_x_axis"/>
    </joint>

    <link name="link1"/>

    <link name="link1_x_axis">
        <visual>
            <origin xyz="0 0 0.25" rpy="0 0 0"/>
            <material name="red"/>
            <geometry>
                <cylinder length="0.5" radius="0.05"/>
            </geometry>
        </visual>
    </link>

    <joint name="q1" type="revolute">
        <origin xyz="0 0 1" rpy="0 0 0"/>
        <parent link="link0_passive"/>
        <child link="link1"/>
        <axis xyz="0 0 1"/>
        <limit effort="100" velocity="2" lower="-1.57" upper="1.57"/>
    </joint>

    <joint name="q1_passive" type="fixed">
        <origin xyz="0 0 0" rpy="1.5707963267948966 0 0"/>
        <parent link="link1"/>
        <child link="link1_passive"/>
    </joint>

    <link name="link1_passive">
        <visual>
            <origin xyz="0 0 0.25" rpy="0 0 0"/>
            <material name="blue"/>
            <geometry>
                <cylinder length="0.5" radius="0.05"/>
            </geometry>
        </visual>
    </link>

    <joint name="q1_x" type="fixed">
        <origin xyz="0 0 0" rpy="0 1.571 0"/>
        <parent link="link1_passive"/>
        <child link="link1_x_axis"/>
    </joint>

    <link name="link2"/>

    <link name="link2_x_axis">
        <visual>
            <origin xyz="0 0 0.25" rpy="0 0 0"/>
            <material name="red"/>
            <geometry>
                <cylinder length="0.5" radius="0.05"/>
            </geometry>
        </visual>
    </link>

    <joint name="q2" type="revolute">
        <origin xyz="0 0 0" rpy="0 0 0"/>
        <parent link="link1_passive"/>
        <child link="link2"/>
        <axis xyz="0 0 1"/>
        <limit effort="100" velocity="2" lower="-1.57" upper="1.57"/>
    </joint>

    <joint name="q2_passive" type="fixed">
        <origin xyz="0.5 0 0" rpy="0 0 0"/>
        <parent link="link2"/>
        <child link="link2_passive"/>
    </joint>

    <link name="link2_passive">
        <visual>
            <origin xyz="0 0 0.25" rpy="0 0 0"/>
            <material name="blue"/>
            <geometry>
                <cylinder length="0.5" radius="0.05"/>
            </geometry>
        </visual>
    </link>

    <joint name="q2_x" type="fixed">
        <origin xyz="0 0 0" rpy="0 1.571 0"/>
        <parent link="link2_passive"/>
        <child link="link2_x_axis"/>
    </joint>

    <link name="link3"/>

    <link name="link3_x_axis">
        <visual>
            <origin xyz="0 0 0.25" rpy="0 0 0"/>
            <material name="red"/>
            <geometry>
                <cylinder length="0.5" radius="0.05"/>
            </geometry>
        </visual>
    </link>

    <joint name="q3" type="revolute">
        <origin xyz="0 0 0" rpy="0 0 0"/>
        <parent link="link2_passive"/>
        <child link="link3"/>
        <axis xyz="0 0 1"/>
        <limit effort="100" velocity="2" lower="-1.57" upper="1.57"/>
    </joint>

    <joint name="q3_passive" type="fixed">
        <origin xyz="0.3 0 0" rpy="0 0 0"/>
        <parent link="link3"/>
        <child link="link3_passive"/>
    </joint>

    <link name="link3_passive">
        <visual>
            <origin xyz="0 0 0.25" rpy="0 0 0"/>
            <material name="blue"/>
            <geometry>
                <cylinder length="0.5" radius="0.05"/>
            </geometry>
        </visual>
    </link>

    <joint name="q3_x" type="fixed">
        <origin xyz="0 0 0" rpy="0 1.571 0"/>
        <parent link="link3_passive"/>
        <child link="link3_x_axis"/>
    </joint>

    
    <link name="gripper_base">
        <visual>
            <origin xyz="0 0 0.05" rpy="0 0 0"/>
            <material name="blue"/>
            <geometry>
                <box size="0.1 0.1 0.1"/>
            </geometry>
        </visual>
    </link>

    
    <joint name="gripper_slide" type="prismatic">
        <origin xyz="0.3 0 0" rpy="0 0 0"/>
        <parent link="link3_passive"/>
        <child link="gripper_base"/>
        <axis xyz="1 0 0"/>
        <limit lower="0" upper="0.05" effort="10" velocity="0.1"/>
    </joint>

    
    <link name="finger_left">
        <visual>
            <origin xyz="0.05 0 0" rpy="0 0 0"/>
            <material name="red"/>
            <geometry>
                <box size="0.02 0.06 0.1"/>
            </geometry>
        </visual>
    </link>

    
    <link name="finger_right">
        <visual>
            <origin xyz="-0.05 0 0" rpy="0 0 0"/>
            <material name="red"/>
            <geometry>
                <box size="0.02 0.06 0.1"/>
            </geometry>
        </visual>
    </link>

    
    <joint name="finger_left_joint" type="prismatic">
        <origin xyz="0.05 0 0" rpy="0 0 0"/>
        <parent link="gripper_base"/>
        <child link="finger_left"/>
        <axis xyz="1 0 0"/>
        <limit lower="0" upper="0.02" effort="5" velocity="0.1"/>
    </joint>

    
    <joint name="finger_right_joint" type="prismatic">
        <origin xyz="0 0 -0.05" rpy="0 0 0"/>
        <parent link="gripper_base"/>
        <child link="finger_right"/>
        <axis xyz="-1 0 0"/>
        <limit lower="0" upper="0.02" effort="5" velocity="0.1"/>
    </joint>

</robot>
